Internal Server Error: /proxy_check
Traceback (most recent call last):
  File "/home/v4proxy/env/lib/python3.10/site-packages/django/core/handlers/exception.py", line 55, in inner
    response = get_response(request)
  File "/home/v4proxy/env/lib/python3.10/site-packages/django/core/handlers/base.py", line 197, in _get_response
    response = wrapped_callback(request, *callback_args, **callback_kwargs)
  File "/home/v4proxy/front/views.py", line 57, in proxy_check
    is_active, response_time = check_proxy(proxy)
  File "/home/v4proxy/front/views.py", line 20, in check_proxy
    formatted_proxy = format_proxy(proxy)
  File "/home/v4proxy/front/views.py", line 10, in format_proxy
    ip, port, username, password = proxy.split(':')
ValueError: too many values to unpack (expected 4)
Internal Server Error: /proxy_check
Traceback (most recent call last):
  File "/home/v4proxy/env/lib/python3.10/site-packages/django/core/handlers/exception.py", line 55, in inner
    response = get_response(request)
  File "/home/v4proxy/env/lib/python3.10/site-packages/django/core/handlers/base.py", line 197, in _get_response
    response = wrapped_callback(request, *callback_args, **callback_kwargs)
  File "/home/v4proxy/front/views.py", line 61, in proxy_check
    results = check_proxy(proxy_list)  # Tüm sonuçları burada alın
  File "/home/v4proxy/front/views.py", line 26, in check_proxy
    is_active, response_time = check_proxy_sync(proxy)
  File "/home/v4proxy/front/views.py", line 32, in check_proxy_sync
    formatted_proxy = format_proxy(proxy)
  File "/home/v4proxy/front/views.py", line 14, in format_proxy
    ip, port, username, password = proxy.split(':')
ValueError: not enough values to unpack (expected 4, got 2)
Internal Server Error: /proxy_check
Traceback (most recent call last):
  File "/home/v4proxy/env/lib/python3.10/site-packages/django/core/handlers/exception.py", line 55, in inner
    response = get_response(request)
  File "/home/v4proxy/env/lib/python3.10/site-packages/django/core/handlers/base.py", line 197, in _get_response
    response = wrapped_callback(request, *callback_args, **callback_kwargs)
  File "/home/v4proxy/front/views.py", line 61, in proxy_check
    results = check_proxy(proxy_list)  # Tüm sonuçları burada alın
  File "/home/v4proxy/front/views.py", line 26, in check_proxy
    is_active, response_time = check_proxy_sync(proxy)
  File "/home/v4proxy/front/views.py", line 32, in check_proxy_sync
    formatted_proxy = format_proxy(proxy)
  File "/home/v4proxy/front/views.py", line 14, in format_proxy
    ip, port, username, password = proxy.split(':')
ValueError: not enough values to unpack (expected 4, got 2)
Internal Server Error: /proxy_check
Traceback (most recent call last):
  File "/home/v4proxy/env/lib/python3.10/site-packages/django/core/handlers/exception.py", line 55, in inner
    response = get_response(request)
  File "/home/v4proxy/env/lib/python3.10/site-packages/django/core/handlers/base.py", line 197, in _get_response
    response = wrapped_callback(request, *callback_args, **callback_kwargs)
  File "/home/v4proxy/front/views.py", line 42, in proxy_check
    return render(request, 'front/proxy_check.html', {'form': form, 'result': result})
  File "/home/v4proxy/env/lib/python3.10/site-packages/django/shortcuts.py", line 24, in render
    content = loader.render_to_string(template_name, context, request, using=using)
  File "/home/v4proxy/env/lib/python3.10/site-packages/django/template/loader.py", line 62, in render_to_string
    return template.render(context, request)
  File "/home/v4proxy/env/lib/python3.10/site-packages/django/template/backends/django.py", line 61, in render
    return self.template.render(context)
  File "/home/v4proxy/env/lib/python3.10/site-packages/django/template/base.py", line 175, in render
    return self._render(context)
  File "/home/v4proxy/env/lib/python3.10/site-packages/django/template/base.py", line 167, in _render
    return self.nodelist.render(context)
  File "/home/v4proxy/env/lib/python3.10/site-packages/django/template/base.py", line 1005, in render
    return SafeString("".join([node.render_annotated(context) for node in self]))
  File "/home/v4proxy/env/lib/python3.10/site-packages/django/template/base.py", line 1005, in <listcomp>
    return SafeString("".join([node.render_annotated(context) for node in self]))
  File "/home/v4proxy/env/lib/python3.10/site-packages/django/template/base.py", line 966, in render_annotated
    return self.render(context)
  File "/home/v4proxy/env/lib/python3.10/site-packages/django/template/defaulttags.py", line 321, in render
    return nodelist.render(context)
  File "/home/v4proxy/env/lib/python3.10/site-packages/django/template/base.py", line 1005, in render
    return SafeString("".join([node.render_annotated(context) for node in self]))
  File "/home/v4proxy/env/lib/python3.10/site-packages/django/template/base.py", line 1005, in <listcomp>
    return SafeString("".join([node.render_annotated(context) for node in self]))
  File "/home/v4proxy/env/lib/python3.10/site-packages/django/template/base.py", line 966, in render_annotated
    return self.render(context)
  File "/home/v4proxy/env/lib/python3.10/site-packages/django/template/defaulttags.py", line 226, in render
    raise ValueError(
ValueError: Need 4 values to unpack in for loop; got 3. 
Internal Server Error: /
Traceback (most recent call last):
  File "/home/v4proxy/env/lib/python3.10/site-packages/django/core/handlers/exception.py", line 55, in inner
    response = get_response(request)
  File "/home/v4proxy/env/lib/python3.10/site-packages/django/core/handlers/base.py", line 197, in _get_response
    response = wrapped_callback(request, *callback_args, **callback_kwargs)
  File "/home/v4proxy/front/views.py", line 7, in index
    return render(request,"front/base/index.html")
  File "/home/v4proxy/env/lib/python3.10/site-packages/django/shortcuts.py", line 24, in render
    content = loader.render_to_string(template_name, context, request, using=using)
  File "/home/v4proxy/env/lib/python3.10/site-packages/django/template/loader.py", line 61, in render_to_string
    template = get_template(template_name, using=using)
  File "/home/v4proxy/env/lib/python3.10/site-packages/django/template/loader.py", line 15, in get_template
    return engine.get_template(template_name)
  File "/home/v4proxy/env/lib/python3.10/site-packages/django/template/backends/django.py", line 33, in get_template
    return Template(self.engine.get_template(template_name), self)
  File "/home/v4proxy/env/lib/python3.10/site-packages/django/template/engine.py", line 175, in get_template
    template, origin = self.find_template(template_name)
  File "/home/v4proxy/env/lib/python3.10/site-packages/django/template/engine.py", line 157, in find_template
    template = loader.get_template(name, skip=skip)
  File "/home/v4proxy/env/lib/python3.10/site-packages/django/template/loaders/cached.py", line 57, in get_template
    template = super().get_template(template_name, skip)
  File "/home/v4proxy/env/lib/python3.10/site-packages/django/template/loaders/base.py", line 28, in get_template
    return Template(
  File "/home/v4proxy/env/lib/python3.10/site-packages/django/template/base.py", line 154, in __init__
    self.nodelist = self.compile_nodelist()
  File "/home/v4proxy/env/lib/python3.10/site-packages/django/template/base.py", line 200, in compile_nodelist
    return parser.parse()
  File "/home/v4proxy/env/lib/python3.10/site-packages/django/template/base.py", line 513, in parse
    raise self.error(token, e)
  File "/home/v4proxy/env/lib/python3.10/site-packages/django/template/base.py", line 511, in parse
    compiled_result = compile_func(self, token)
  File "/home/v4proxy/env/lib/python3.10/site-packages/django/templatetags/i18n.py", line 403, in do_translate
    message_string = parser.compile_filter(bits[1])
  File "/home/v4proxy/env/lib/python3.10/site-packages/django/template/base.py", line 600, in compile_filter
    return FilterExpression(token, self)
  File "/home/v4proxy/env/lib/python3.10/site-packages/django/template/base.py", line 703, in __init__
    raise TemplateSyntaxError(
django.template.exceptions.TemplateSyntaxError: Could not parse the remainder: 'ler' from ''IPv6 Proxy'ler'
Internal Server Error: /
Traceback (most recent call last):
  File "/home/v4proxy/env/lib/python3.10/site-packages/django/core/handlers/exception.py", line 55, in inner
    response = get_response(request)
  File "/home/v4proxy/env/lib/python3.10/site-packages/django/core/handlers/base.py", line 197, in _get_response
    response = wrapped_callback(request, *callback_args, **callback_kwargs)
  File "/home/v4proxy/front/views.py", line 7, in index
    return render(request,"front/base/index.html")
  File "/home/v4proxy/env/lib/python3.10/site-packages/django/shortcuts.py", line 24, in render
    content = loader.render_to_string(template_name, context, request, using=using)
  File "/home/v4proxy/env/lib/python3.10/site-packages/django/template/loader.py", line 61, in render_to_string
    template = get_template(template_name, using=using)
  File "/home/v4proxy/env/lib/python3.10/site-packages/django/template/loader.py", line 15, in get_template
    return engine.get_template(template_name)
  File "/home/v4proxy/env/lib/python3.10/site-packages/django/template/backends/django.py", line 33, in get_template
    return Template(self.engine.get_template(template_name), self)
  File "/home/v4proxy/env/lib/python3.10/site-packages/django/template/engine.py", line 175, in get_template
    template, origin = self.find_template(template_name)
  File "/home/v4proxy/env/lib/python3.10/site-packages/django/template/engine.py", line 157, in find_template
    template = loader.get_template(name, skip=skip)
  File "/home/v4proxy/env/lib/python3.10/site-packages/django/template/loaders/cached.py", line 57, in get_template
    template = super().get_template(template_name, skip)
  File "/home/v4proxy/env/lib/python3.10/site-packages/django/template/loaders/base.py", line 28, in get_template
    return Template(
  File "/home/v4proxy/env/lib/python3.10/site-packages/django/template/base.py", line 154, in __init__
    self.nodelist = self.compile_nodelist()
  File "/home/v4proxy/env/lib/python3.10/site-packages/django/template/base.py", line 200, in compile_nodelist
    return parser.parse()
  File "/home/v4proxy/env/lib/python3.10/site-packages/django/template/base.py", line 513, in parse
    raise self.error(token, e)
  File "/home/v4proxy/env/lib/python3.10/site-packages/django/template/base.py", line 511, in parse
    compiled_result = compile_func(self, token)
  File "/home/v4proxy/env/lib/python3.10/site-packages/django/templatetags/i18n.py", line 403, in do_translate
    message_string = parser.compile_filter(bits[1])
  File "/home/v4proxy/env/lib/python3.10/site-packages/django/template/base.py", line 600, in compile_filter
    return FilterExpression(token, self)
  File "/home/v4proxy/env/lib/python3.10/site-packages/django/template/base.py", line 703, in __init__
    raise TemplateSyntaxError(
django.template.exceptions.TemplateSyntaxError: Could not parse the remainder: 'nin' from ''Sosyal Medya ve E-Ticaret Dünyasında IPv6 Proxy'nin'
Internal Server Error: /
Traceback (most recent call last):
  File "/home/v4proxy/env/lib/python3.10/site-packages/django/core/handlers/exception.py", line 55, in inner
    response = get_response(request)
  File "/home/v4proxy/env/lib/python3.10/site-packages/django/core/handlers/base.py", line 197, in _get_response
    response = wrapped_callback(request, *callback_args, **callback_kwargs)
  File "/home/v4proxy/front/views.py", line 7, in index
    return render(request,"front/base/index.html")
  File "/home/v4proxy/env/lib/python3.10/site-packages/django/shortcuts.py", line 24, in render
    content = loader.render_to_string(template_name, context, request, using=using)
  File "/home/v4proxy/env/lib/python3.10/site-packages/django/template/loader.py", line 62, in render_to_string
    return template.render(context, request)
  File "/home/v4proxy/env/lib/python3.10/site-packages/django/template/backends/django.py", line 61, in render
    return self.template.render(context)
  File "/home/v4proxy/env/lib/python3.10/site-packages/django/template/base.py", line 175, in render
    return self._render(context)
  File "/home/v4proxy/env/lib/python3.10/site-packages/django/template/base.py", line 167, in _render
    return self.nodelist.render(context)
  File "/home/v4proxy/env/lib/python3.10/site-packages/django/template/base.py", line 1005, in render
    return SafeString("".join([node.render_annotated(context) for node in self]))
  File "/home/v4proxy/env/lib/python3.10/site-packages/django/template/base.py", line 1005, in <listcomp>
    return SafeString("".join([node.render_annotated(context) for node in self]))
  File "/home/v4proxy/env/lib/python3.10/site-packages/django/template/base.py", line 966, in render_annotated
    return self.render(context)
  File "/home/v4proxy/env/lib/python3.10/site-packages/django/template/loader_tags.py", line 208, in render
    return template.render(context)
  File "/home/v4proxy/env/lib/python3.10/site-packages/django/template/base.py", line 177, in render
    return self._render(context)
  File "/home/v4proxy/env/lib/python3.10/site-packages/django/template/base.py", line 167, in _render
    return self.nodelist.render(context)
  File "/home/v4proxy/env/lib/python3.10/site-packages/django/template/base.py", line 1005, in render
    return SafeString("".join([node.render_annotated(context) for node in self]))
  File "/home/v4proxy/env/lib/python3.10/site-packages/django/template/base.py", line 1005, in <listcomp>
    return SafeString("".join([node.render_annotated(context) for node in self]))
  File "/home/v4proxy/env/lib/python3.10/site-packages/django/template/base.py", line 966, in render_annotated
    return self.render(context)
  File "/home/v4proxy/env/lib/python3.10/site-packages/django/template/defaulttags.py", line 471, in render
    url = reverse(view_name, args=args, kwargs=kwargs, current_app=current_app)
  File "/home/v4proxy/env/lib/python3.10/site-packages/django/urls/base.py", line 88, in reverse
    return resolver._reverse_with_prefix(view, prefix, *args, **kwargs)
  File "/home/v4proxy/env/lib/python3.10/site-packages/django/urls/resolvers.py", line 828, in _reverse_with_prefix
    raise NoReverseMatch(msg)
django.urls.exceptions.NoReverseMatch: Reverse for 'panel' not found. 'panel' is not a valid view function or pattern name.
Internal Server Error: /panel/register
Traceback (most recent call last):
  File "/home/v4proxy/env/lib/python3.10/site-packages/django/core/handlers/exception.py", line 55, in inner
    response = get_response(request)
  File "/home/v4proxy/env/lib/python3.10/site-packages/django/core/handlers/base.py", line 197, in _get_response
    response = wrapped_callback(request, *callback_args, **callback_kwargs)
  File "/home/v4proxy/panel/views.py", line 115, in register
    return render(request,"admin/login/register.html")
  File "/home/v4proxy/env/lib/python3.10/site-packages/django/shortcuts.py", line 24, in render
    content = loader.render_to_string(template_name, context, request, using=using)
  File "/home/v4proxy/env/lib/python3.10/site-packages/django/template/loader.py", line 61, in render_to_string
    template = get_template(template_name, using=using)
  File "/home/v4proxy/env/lib/python3.10/site-packages/django/template/loader.py", line 15, in get_template
    return engine.get_template(template_name)
  File "/home/v4proxy/env/lib/python3.10/site-packages/django/template/backends/django.py", line 33, in get_template
    return Template(self.engine.get_template(template_name), self)
  File "/home/v4proxy/env/lib/python3.10/site-packages/django/template/engine.py", line 175, in get_template
    template, origin = self.find_template(template_name)
  File "/home/v4proxy/env/lib/python3.10/site-packages/django/template/engine.py", line 157, in find_template
    template = loader.get_template(name, skip=skip)
  File "/home/v4proxy/env/lib/python3.10/site-packages/django/template/loaders/cached.py", line 57, in get_template
    template = super().get_template(template_name, skip)
  File "/home/v4proxy/env/lib/python3.10/site-packages/django/template/loaders/base.py", line 28, in get_template
    return Template(
  File "/home/v4proxy/env/lib/python3.10/site-packages/django/template/base.py", line 154, in __init__
    self.nodelist = self.compile_nodelist()
  File "/home/v4proxy/env/lib/python3.10/site-packages/django/template/base.py", line 200, in compile_nodelist
    return parser.parse()
  File "/home/v4proxy/env/lib/python3.10/site-packages/django/template/base.py", line 514, in parse
    self.extend_nodelist(nodelist, compiled_result, token)
  File "/home/v4proxy/env/lib/python3.10/site-packages/django/template/base.py", line 531, in extend_nodelist
    raise self.error(
django.template.exceptions.TemplateSyntaxError: <ExtendsNode: extends 'admin/login/base.html'> must be the first tag in the template.
Internal Server Error: /panel/register
Traceback (most recent call last):
  File "/home/v4proxy/env/lib/python3.10/site-packages/django/core/handlers/exception.py", line 55, in inner
    response = get_response(request)
  File "/home/v4proxy/env/lib/python3.10/site-packages/django/core/handlers/base.py", line 197, in _get_response
    response = wrapped_callback(request, *callback_args, **callback_kwargs)
  File "/home/v4proxy/panel/views.py", line 115, in register
    return render(request,"admin/login/register.html")
  File "/home/v4proxy/env/lib/python3.10/site-packages/django/shortcuts.py", line 24, in render
    content = loader.render_to_string(template_name, context, request, using=using)
  File "/home/v4proxy/env/lib/python3.10/site-packages/django/template/loader.py", line 61, in render_to_string
    template = get_template(template_name, using=using)
  File "/home/v4proxy/env/lib/python3.10/site-packages/django/template/loader.py", line 15, in get_template
    return engine.get_template(template_name)
  File "/home/v4proxy/env/lib/python3.10/site-packages/django/template/backends/django.py", line 33, in get_template
    return Template(self.engine.get_template(template_name), self)
  File "/home/v4proxy/env/lib/python3.10/site-packages/django/template/engine.py", line 175, in get_template
    template, origin = self.find_template(template_name)
  File "/home/v4proxy/env/lib/python3.10/site-packages/django/template/engine.py", line 157, in find_template
    template = loader.get_template(name, skip=skip)
  File "/home/v4proxy/env/lib/python3.10/site-packages/django/template/loaders/cached.py", line 57, in get_template
    template = super().get_template(template_name, skip)
  File "/home/v4proxy/env/lib/python3.10/site-packages/django/template/loaders/base.py", line 28, in get_template
    return Template(
  File "/home/v4proxy/env/lib/python3.10/site-packages/django/template/base.py", line 154, in __init__
    self.nodelist = self.compile_nodelist()
  File "/home/v4proxy/env/lib/python3.10/site-packages/django/template/base.py", line 200, in compile_nodelist
    return parser.parse()
  File "/home/v4proxy/env/lib/python3.10/site-packages/django/template/base.py", line 514, in parse
    self.extend_nodelist(nodelist, compiled_result, token)
  File "/home/v4proxy/env/lib/python3.10/site-packages/django/template/base.py", line 531, in extend_nodelist
    raise self.error(
django.template.exceptions.TemplateSyntaxError: <ExtendsNode: extends 'admin/login/base.html'> must be the first tag in the template.
Internal Server Error: /panel/login
Traceback (most recent call last):
  File "/home/v4proxy/env/lib/python3.10/site-packages/django/core/handlers/exception.py", line 55, in inner
    response = get_response(request)
  File "/home/v4proxy/env/lib/python3.10/site-packages/django/core/handlers/base.py", line 197, in _get_response
    response = wrapped_callback(request, *callback_args, **callback_kwargs)
  File "/home/v4proxy/panel/views.py", line 91, in login_user
    return redirect('panel:home')
  File "/home/v4proxy/env/lib/python3.10/site-packages/django/shortcuts.py", line 48, in redirect
    return redirect_class(resolve_url(to, *args, **kwargs))
  File "/home/v4proxy/env/lib/python3.10/site-packages/django/shortcuts.py", line 145, in resolve_url
    return reverse(to, args=args, kwargs=kwargs)
  File "/home/v4proxy/env/lib/python3.10/site-packages/django/urls/base.py", line 88, in reverse
    return resolver._reverse_with_prefix(view, prefix, *args, **kwargs)
  File "/home/v4proxy/env/lib/python3.10/site-packages/django/urls/resolvers.py", line 828, in _reverse_with_prefix
    raise NoReverseMatch(msg)
django.urls.exceptions.NoReverseMatch: Reverse for 'home' not found. 'home' is not a valid view function or pattern name.
Internal Server Error: /
Traceback (most recent call last):
  File "/home/v4proxy/env/lib/python3.10/site-packages/django/template/base.py", line 505, in parse
    compile_func = self.tags[command]
KeyError: 'trans'

During handling of the above exception, another exception occurred:

Traceback (most recent call last):
  File "/home/v4proxy/env/lib/python3.10/site-packages/django/core/handlers/exception.py", line 55, in inner
    response = get_response(request)
  File "/home/v4proxy/env/lib/python3.10/site-packages/django/core/handlers/base.py", line 197, in _get_response
    response = wrapped_callback(request, *callback_args, **callback_kwargs)
  File "/home/v4proxy/front/views.py", line 7, in index
    return render(request,"front/base/index.html")
  File "/home/v4proxy/env/lib/python3.10/site-packages/django/shortcuts.py", line 24, in render
    content = loader.render_to_string(template_name, context, request, using=using)
  File "/home/v4proxy/env/lib/python3.10/site-packages/django/template/loader.py", line 62, in render_to_string
    return template.render(context, request)
  File "/home/v4proxy/env/lib/python3.10/site-packages/django/template/backends/django.py", line 61, in render
    return self.template.render(context)
  File "/home/v4proxy/env/lib/python3.10/site-packages/django/template/base.py", line 175, in render
    return self._render(context)
  File "/home/v4proxy/env/lib/python3.10/site-packages/django/template/base.py", line 167, in _render
    return self.nodelist.render(context)
  File "/home/v4proxy/env/lib/python3.10/site-packages/django/template/base.py", line 1005, in render
    return SafeString("".join([node.render_annotated(context) for node in self]))
  File "/home/v4proxy/env/lib/python3.10/site-packages/django/template/base.py", line 1005, in <listcomp>
    return SafeString("".join([node.render_annotated(context) for node in self]))
  File "/home/v4proxy/env/lib/python3.10/site-packages/django/template/base.py", line 966, in render_annotated
    return self.render(context)
  File "/home/v4proxy/env/lib/python3.10/site-packages/django/template/loader_tags.py", line 197, in render
    template = context.template.engine.select_template(template_name)
  File "/home/v4proxy/env/lib/python3.10/site-packages/django/template/engine.py", line 206, in select_template
    return self.get_template(template_name)
  File "/home/v4proxy/env/lib/python3.10/site-packages/django/template/engine.py", line 175, in get_template
    template, origin = self.find_template(template_name)
  File "/home/v4proxy/env/lib/python3.10/site-packages/django/template/engine.py", line 157, in find_template
    template = loader.get_template(name, skip=skip)
  File "/home/v4proxy/env/lib/python3.10/site-packages/django/template/loaders/cached.py", line 57, in get_template
    template = super().get_template(template_name, skip)
  File "/home/v4proxy/env/lib/python3.10/site-packages/django/template/loaders/base.py", line 28, in get_template
    return Template(
  File "/home/v4proxy/env/lib/python3.10/site-packages/django/template/base.py", line 154, in __init__
    self.nodelist = self.compile_nodelist()
  File "/home/v4proxy/env/lib/python3.10/site-packages/django/template/base.py", line 200, in compile_nodelist
    return parser.parse()
  File "/home/v4proxy/env/lib/python3.10/site-packages/django/template/base.py", line 507, in parse
    self.invalid_block_tag(token, command, parse_until)
  File "/home/v4proxy/env/lib/python3.10/site-packages/django/template/base.py", line 568, in invalid_block_tag
    raise self.error(
django.template.exceptions.TemplateSyntaxError: Invalid block tag on line 9: 'trans'. Did you forget to register or load this tag?
Internal Server Error: /
Traceback (most recent call last):
  File "/home/v4proxy/env/lib/python3.10/site-packages/django/template/base.py", line 505, in parse
    compile_func = self.tags[command]
KeyError: 'trans'

During handling of the above exception, another exception occurred:

Traceback (most recent call last):
  File "/home/v4proxy/env/lib/python3.10/site-packages/django/core/handlers/exception.py", line 55, in inner
    response = get_response(request)
  File "/home/v4proxy/env/lib/python3.10/site-packages/django/core/handlers/base.py", line 197, in _get_response
    response = wrapped_callback(request, *callback_args, **callback_kwargs)
  File "/home/v4proxy/front/views.py", line 7, in index
    return render(request,"front/base/index.html")
  File "/home/v4proxy/env/lib/python3.10/site-packages/django/shortcuts.py", line 24, in render
    content = loader.render_to_string(template_name, context, request, using=using)
  File "/home/v4proxy/env/lib/python3.10/site-packages/django/template/loader.py", line 62, in render_to_string
    return template.render(context, request)
  File "/home/v4proxy/env/lib/python3.10/site-packages/django/template/backends/django.py", line 61, in render
    return self.template.render(context)
  File "/home/v4proxy/env/lib/python3.10/site-packages/django/template/base.py", line 175, in render
    return self._render(context)
  File "/home/v4proxy/env/lib/python3.10/site-packages/django/template/base.py", line 167, in _render
    return self.nodelist.render(context)
  File "/home/v4proxy/env/lib/python3.10/site-packages/django/template/base.py", line 1005, in render
    return SafeString("".join([node.render_annotated(context) for node in self]))
  File "/home/v4proxy/env/lib/python3.10/site-packages/django/template/base.py", line 1005, in <listcomp>
    return SafeString("".join([node.render_annotated(context) for node in self]))
  File "/home/v4proxy/env/lib/python3.10/site-packages/django/template/base.py", line 966, in render_annotated
    return self.render(context)
  File "/home/v4proxy/env/lib/python3.10/site-packages/django/template/loader_tags.py", line 197, in render
    template = context.template.engine.select_template(template_name)
  File "/home/v4proxy/env/lib/python3.10/site-packages/django/template/engine.py", line 206, in select_template
    return self.get_template(template_name)
  File "/home/v4proxy/env/lib/python3.10/site-packages/django/template/engine.py", line 175, in get_template
    template, origin = self.find_template(template_name)
  File "/home/v4proxy/env/lib/python3.10/site-packages/django/template/engine.py", line 157, in find_template
    template = loader.get_template(name, skip=skip)
  File "/home/v4proxy/env/lib/python3.10/site-packages/django/template/loaders/cached.py", line 57, in get_template
    template = super().get_template(template_name, skip)
  File "/home/v4proxy/env/lib/python3.10/site-packages/django/template/loaders/base.py", line 28, in get_template
    return Template(
  File "/home/v4proxy/env/lib/python3.10/site-packages/django/template/base.py", line 154, in __init__
    self.nodelist = self.compile_nodelist()
  File "/home/v4proxy/env/lib/python3.10/site-packages/django/template/base.py", line 200, in compile_nodelist
    return parser.parse()
  File "/home/v4proxy/env/lib/python3.10/site-packages/django/template/base.py", line 507, in parse
    self.invalid_block_tag(token, command, parse_until)
  File "/home/v4proxy/env/lib/python3.10/site-packages/django/template/base.py", line 568, in invalid_block_tag
    raise self.error(
django.template.exceptions.TemplateSyntaxError: Invalid block tag on line 10: 'trans'. Did you forget to register or load this tag?
Internal Server Error: /
Traceback (most recent call last):
  File "/home/v4proxy/env/lib/python3.10/site-packages/django/template/base.py", line 505, in parse
    compile_func = self.tags[command]
KeyError: 'static'

During handling of the above exception, another exception occurred:

Traceback (most recent call last):
  File "/home/v4proxy/env/lib/python3.10/site-packages/django/core/handlers/exception.py", line 55, in inner
    response = get_response(request)
  File "/home/v4proxy/env/lib/python3.10/site-packages/django/core/handlers/base.py", line 197, in _get_response
    response = wrapped_callback(request, *callback_args, **callback_kwargs)
  File "/home/v4proxy/front/views.py", line 7, in index
    return render(request,"front/base/index.html")
  File "/home/v4proxy/env/lib/python3.10/site-packages/django/shortcuts.py", line 24, in render
    content = loader.render_to_string(template_name, context, request, using=using)
  File "/home/v4proxy/env/lib/python3.10/site-packages/django/template/loader.py", line 62, in render_to_string
    return template.render(context, request)
  File "/home/v4proxy/env/lib/python3.10/site-packages/django/template/backends/django.py", line 61, in render
    return self.template.render(context)
  File "/home/v4proxy/env/lib/python3.10/site-packages/django/template/base.py", line 175, in render
    return self._render(context)
  File "/home/v4proxy/env/lib/python3.10/site-packages/django/template/base.py", line 167, in _render
    return self.nodelist.render(context)
  File "/home/v4proxy/env/lib/python3.10/site-packages/django/template/base.py", line 1005, in render
    return SafeString("".join([node.render_annotated(context) for node in self]))
  File "/home/v4proxy/env/lib/python3.10/site-packages/django/template/base.py", line 1005, in <listcomp>
    return SafeString("".join([node.render_annotated(context) for node in self]))
  File "/home/v4proxy/env/lib/python3.10/site-packages/django/template/base.py", line 966, in render_annotated
    return self.render(context)
  File "/home/v4proxy/env/lib/python3.10/site-packages/django/template/loader_tags.py", line 197, in render
    template = context.template.engine.select_template(template_name)
  File "/home/v4proxy/env/lib/python3.10/site-packages/django/template/engine.py", line 206, in select_template
    return self.get_template(template_name)
  File "/home/v4proxy/env/lib/python3.10/site-packages/django/template/engine.py", line 175, in get_template
    template, origin = self.find_template(template_name)
  File "/home/v4proxy/env/lib/python3.10/site-packages/django/template/engine.py", line 157, in find_template
    template = loader.get_template(name, skip=skip)
  File "/home/v4proxy/env/lib/python3.10/site-packages/django/template/loaders/cached.py", line 57, in get_template
    template = super().get_template(template_name, skip)
  File "/home/v4proxy/env/lib/python3.10/site-packages/django/template/loaders/base.py", line 28, in get_template
    return Template(
  File "/home/v4proxy/env/lib/python3.10/site-packages/django/template/base.py", line 154, in __init__
    self.nodelist = self.compile_nodelist()
  File "/home/v4proxy/env/lib/python3.10/site-packages/django/template/base.py", line 200, in compile_nodelist
    return parser.parse()
  File "/home/v4proxy/env/lib/python3.10/site-packages/django/template/base.py", line 507, in parse
    self.invalid_block_tag(token, command, parse_until)
  File "/home/v4proxy/env/lib/python3.10/site-packages/django/template/base.py", line 568, in invalid_block_tag
    raise self.error(
django.template.exceptions.TemplateSyntaxError: Invalid block tag on line 1: 'static'. Did you forget to register or load this tag?
Internal Server Error: /proxy_check
Traceback (most recent call last):
  File "/home/v4proxy/env/lib/python3.10/site-packages/django/core/handlers/exception.py", line 55, in inner
    response = get_response(request)
  File "/home/v4proxy/env/lib/python3.10/site-packages/django/core/handlers/base.py", line 197, in _get_response
    response = wrapped_callback(request, *callback_args, **callback_kwargs)
  File "/home/v4proxy/front/views.py", line 64, in proxy_check
    results = check_proxy(proxy_list)  # Tüm sonuçları burada alın
  File "/home/v4proxy/front/views.py", line 29, in check_proxy
    is_active, response_time = check_proxy_sync(proxy)
  File "/home/v4proxy/front/views.py", line 35, in check_proxy_sync
    formatted_proxy = format_proxy(proxy)
  File "/home/v4proxy/front/views.py", line 16, in format_proxy
    ip, port, username, password = i.split(':')
ValueError: not enough values to unpack (expected 4, got 1)
Internal Server Error: /panel/register
Traceback (most recent call last):
  File "/home/v4proxy/env/lib/python3.10/site-packages/django/core/handlers/exception.py", line 55, in inner
    response = get_response(request)
  File "/home/v4proxy/env/lib/python3.10/site-packages/django/core/handlers/base.py", line 197, in _get_response
    response = wrapped_callback(request, *callback_args, **callback_kwargs)
  File "/home/v4proxy/panel/views.py", line 103, in register
    if User.objects.filter(email=email).exists():
  File "/home/v4proxy/env/lib/python3.10/site-packages/django/db/models/manager.py", line 196, in __get__
    raise AttributeError(
AttributeError: Manager isn't available; 'auth.User' has been swapped for 'panel.user'
Internal Server Error: /proxy_check
Traceback (most recent call last):
  File "/home/v4proxy/env/lib/python3.10/site-packages/django/core/handlers/exception.py", line 55, in inner
    response = get_response(request)
  File "/home/v4proxy/env/lib/python3.10/site-packages/django/core/handlers/base.py", line 197, in _get_response
    response = wrapped_callback(request, *callback_args, **callback_kwargs)
  File "/home/v4proxy/front/views.py", line 68, in proxy_check
    return render(request, 'front/proxy_check.html', {'form': form, 'result': proxy_list})
UnboundLocalError: local variable 'proxy_list' referenced before assignment
Internal Server Error: /proxy_check
Traceback (most recent call last):
  File "/home/v4proxy/env/lib/python3.10/site-packages/django/core/handlers/exception.py", line 55, in inner
    response = get_response(request)
  File "/home/v4proxy/env/lib/python3.10/site-packages/django/core/handlers/base.py", line 197, in _get_response
    response = wrapped_callback(request, *callback_args, **callback_kwargs)
  File "/home/v4proxy/front/views.py", line 68, in proxy_check
    return render(request, 'front/proxy_check.html', {'form': form, 'result': results})
UnboundLocalError: local variable 'results' referenced before assignment
Internal Server Error: /proxy_check
Traceback (most recent call last):
  File "/home/v4proxy/env/lib/python3.10/site-packages/django/core/handlers/exception.py", line 55, in inner
    response = get_response(request)
  File "/home/v4proxy/env/lib/python3.10/site-packages/django/core/handlers/base.py", line 197, in _get_response
    response = wrapped_callback(request, *callback_args, **callback_kwargs)
  File "/home/v4proxy/front/views.py", line 67, in proxy_check
    return render(request, 'front/proxy_check.html', {'form': form, 'result': proxy_list})
UnboundLocalError: local variable 'proxy_list' referenced before assignment
Internal Server Error: /proxy_check
Traceback (most recent call last):
  File "/home/v4proxy/env/lib/python3.10/site-packages/django/core/handlers/exception.py", line 55, in inner
    response = get_response(request)
  File "/home/v4proxy/env/lib/python3.10/site-packages/django/core/handlers/base.py", line 204, in _get_response
    self.check_response(response, callback)
  File "/home/v4proxy/env/lib/python3.10/site-packages/django/core/handlers/base.py", line 332, in check_response
    raise ValueError(
ValueError: The view front.views.proxy_check didn't return an HttpResponse object. It returned None instead.
Internal Server Error: /proxy_check
Traceback (most recent call last):
  File "/home/v4proxy/env/lib/python3.10/site-packages/django/core/handlers/exception.py", line 55, in inner
    response = get_response(request)
  File "/home/v4proxy/env/lib/python3.10/site-packages/django/core/handlers/base.py", line 197, in _get_response
    response = wrapped_callback(request, *callback_args, **callback_kwargs)
  File "/home/v4proxy/front/views.py", line 67, in proxy_check
    return render(request, 'front/proxy_check.html', {'form': form, 'result': form.cleaned_data['proxy_data'].split('\n')})
  File "/home/v4proxy/env/lib/python3.10/site-packages/django/shortcuts.py", line 24, in render
    content = loader.render_to_string(template_name, context, request, using=using)
  File "/home/v4proxy/env/lib/python3.10/site-packages/django/template/loader.py", line 62, in render_to_string
    return template.render(context, request)
  File "/home/v4proxy/env/lib/python3.10/site-packages/django/template/backends/django.py", line 61, in render
    return self.template.render(context)
  File "/home/v4proxy/env/lib/python3.10/site-packages/django/template/base.py", line 175, in render
    return self._render(context)
  File "/home/v4proxy/env/lib/python3.10/site-packages/django/template/base.py", line 167, in _render
    return self.nodelist.render(context)
  File "/home/v4proxy/env/lib/python3.10/site-packages/django/template/base.py", line 1005, in render
    return SafeString("".join([node.render_annotated(context) for node in self]))
  File "/home/v4proxy/env/lib/python3.10/site-packages/django/template/base.py", line 1005, in <listcomp>
    return SafeString("".join([node.render_annotated(context) for node in self]))
  File "/home/v4proxy/env/lib/python3.10/site-packages/django/template/base.py", line 966, in render_annotated
    return self.render(context)
  File "/home/v4proxy/env/lib/python3.10/site-packages/django/template/defaulttags.py", line 321, in render
    return nodelist.render(context)
  File "/home/v4proxy/env/lib/python3.10/site-packages/django/template/base.py", line 1005, in render
    return SafeString("".join([node.render_annotated(context) for node in self]))
  File "/home/v4proxy/env/lib/python3.10/site-packages/django/template/base.py", line 1005, in <listcomp>
    return SafeString("".join([node.render_annotated(context) for node in self]))
  File "/home/v4proxy/env/lib/python3.10/site-packages/django/template/base.py", line 966, in render_annotated
    return self.render(context)
  File "/home/v4proxy/env/lib/python3.10/site-packages/django/template/defaulttags.py", line 226, in render
    raise ValueError(
ValueError: Need 4 values to unpack in for loop; got 34. 
Internal Server Error: /proxy_check
Traceback (most recent call last):
  File "/home/v4proxy/env/lib/python3.10/site-packages/django/template/base.py", line 505, in parse
    compile_func = self.tags[command]
KeyError: 'a'

During handling of the above exception, another exception occurred:

Traceback (most recent call last):
  File "/home/v4proxy/env/lib/python3.10/site-packages/django/core/handlers/exception.py", line 55, in inner
    response = get_response(request)
  File "/home/v4proxy/env/lib/python3.10/site-packages/django/core/handlers/base.py", line 197, in _get_response
    response = wrapped_callback(request, *callback_args, **callback_kwargs)
  File "/home/v4proxy/front/views.py", line 65, in proxy_check
    return render(request, 'front/proxy_check.html', {'form': form, 'result': result , 'a' :results })
  File "/home/v4proxy/env/lib/python3.10/site-packages/django/shortcuts.py", line 24, in render
    content = loader.render_to_string(template_name, context, request, using=using)
  File "/home/v4proxy/env/lib/python3.10/site-packages/django/template/loader.py", line 61, in render_to_string
    template = get_template(template_name, using=using)
  File "/home/v4proxy/env/lib/python3.10/site-packages/django/template/loader.py", line 15, in get_template
    return engine.get_template(template_name)
  File "/home/v4proxy/env/lib/python3.10/site-packages/django/template/backends/django.py", line 33, in get_template
    return Template(self.engine.get_template(template_name), self)
  File "/home/v4proxy/env/lib/python3.10/site-packages/django/template/engine.py", line 175, in get_template
    template, origin = self.find_template(template_name)
  File "/home/v4proxy/env/lib/python3.10/site-packages/django/template/engine.py", line 157, in find_template
    template = loader.get_template(name, skip=skip)
  File "/home/v4proxy/env/lib/python3.10/site-packages/django/template/loaders/cached.py", line 57, in get_template
    template = super().get_template(template_name, skip)
  File "/home/v4proxy/env/lib/python3.10/site-packages/django/template/loaders/base.py", line 28, in get_template
    return Template(
  File "/home/v4proxy/env/lib/python3.10/site-packages/django/template/base.py", line 154, in __init__
    self.nodelist = self.compile_nodelist()
  File "/home/v4proxy/env/lib/python3.10/site-packages/django/template/base.py", line 200, in compile_nodelist
    return parser.parse()
  File "/home/v4proxy/env/lib/python3.10/site-packages/django/template/base.py", line 513, in parse
    raise self.error(token, e)
  File "/home/v4proxy/env/lib/python3.10/site-packages/django/template/base.py", line 511, in parse
    compiled_result = compile_func(self, token)
  File "/home/v4proxy/env/lib/python3.10/site-packages/django/template/defaulttags.py", line 953, in do_if
    nodelist = parser.parse(("elif", "else", "endif"))
  File "/home/v4proxy/env/lib/python3.10/site-packages/django/template/base.py", line 507, in parse
    self.invalid_block_tag(token, command, parse_until)
  File "/home/v4proxy/env/lib/python3.10/site-packages/django/template/base.py", line 558, in invalid_block_tag
    raise self.error(
django.template.exceptions.TemplateSyntaxError: Invalid block tag on line 17: 'a', expected 'elif', 'else' or 'endif'. Did you forget to register or load this tag?
Internal Server Error: /proxy_check
Traceback (most recent call last):
  File "/home/v4proxy/env/lib/python3.10/site-packages/django/template/base.py", line 505, in parse
    compile_func = self.tags[command]
KeyError: 'a'

During handling of the above exception, another exception occurred:

Traceback (most recent call last):
  File "/home/v4proxy/env/lib/python3.10/site-packages/django/core/handlers/exception.py", line 55, in inner
    response = get_response(request)
  File "/home/v4proxy/env/lib/python3.10/site-packages/django/core/handlers/base.py", line 197, in _get_response
    response = wrapped_callback(request, *callback_args, **callback_kwargs)
  File "/home/v4proxy/front/views.py", line 65, in proxy_check
    return render(request, 'front/proxy_check.html', {'form': form, 'result': result , 'a' :results })
  File "/home/v4proxy/env/lib/python3.10/site-packages/django/shortcuts.py", line 24, in render
    content = loader.render_to_string(template_name, context, request, using=using)
  File "/home/v4proxy/env/lib/python3.10/site-packages/django/template/loader.py", line 61, in render_to_string
    template = get_template(template_name, using=using)
  File "/home/v4proxy/env/lib/python3.10/site-packages/django/template/loader.py", line 15, in get_template
    return engine.get_template(template_name)
  File "/home/v4proxy/env/lib/python3.10/site-packages/django/template/backends/django.py", line 33, in get_template
    return Template(self.engine.get_template(template_name), self)
  File "/home/v4proxy/env/lib/python3.10/site-packages/django/template/engine.py", line 175, in get_template
    template, origin = self.find_template(template_name)
  File "/home/v4proxy/env/lib/python3.10/site-packages/django/template/engine.py", line 157, in find_template
    template = loader.get_template(name, skip=skip)
  File "/home/v4proxy/env/lib/python3.10/site-packages/django/template/loaders/cached.py", line 57, in get_template
    template = super().get_template(template_name, skip)
  File "/home/v4proxy/env/lib/python3.10/site-packages/django/template/loaders/base.py", line 28, in get_template
    return Template(
  File "/home/v4proxy/env/lib/python3.10/site-packages/django/template/base.py", line 154, in __init__
    self.nodelist = self.compile_nodelist()
  File "/home/v4proxy/env/lib/python3.10/site-packages/django/template/base.py", line 200, in compile_nodelist
    return parser.parse()
  File "/home/v4proxy/env/lib/python3.10/site-packages/django/template/base.py", line 507, in parse
    self.invalid_block_tag(token, command, parse_until)
  File "/home/v4proxy/env/lib/python3.10/site-packages/django/template/base.py", line 568, in invalid_block_tag
    raise self.error(
django.template.exceptions.TemplateSyntaxError: Invalid block tag on line 13: 'a'. Did you forget to register or load this tag?
Internal Server Error: /proxy_check
Traceback (most recent call last):
  File "/home/v4proxy/env/lib/python3.10/site-packages/django/core/handlers/exception.py", line 55, in inner
    response = get_response(request)
  File "/home/v4proxy/env/lib/python3.10/site-packages/django/core/handlers/base.py", line 197, in _get_response
    response = wrapped_callback(request, *callback_args, **callback_kwargs)
  File "/home/v4proxy/front/views.py", line 66, in proxy_check
    result.extend(results)  # Sonuçları result listesine ekleyin
TypeError: 'coroutine' object is not iterable
Internal Server Error: /proxy_check
Traceback (most recent call last):
  File "/home/v4proxy/env/lib/python3.10/site-packages/django/core/handlers/exception.py", line 55, in inner
    response = get_response(request)
  File "/home/v4proxy/env/lib/python3.10/site-packages/django/core/handlers/base.py", line 197, in _get_response
    response = wrapped_callback(request, *callback_args, **callback_kwargs)
  File "/home/v4proxy/env/lib/python3.10/site-packages/asgiref/sync.py", line 277, in __call__
    return call_result.result()
  File "/usr/lib/python3.10/concurrent/futures/_base.py", line 451, in result
    return self.__get_result()
  File "/usr/lib/python3.10/concurrent/futures/_base.py", line 403, in __get_result
    raise self._exception
  File "/home/v4proxy/env/lib/python3.10/site-packages/asgiref/sync.py", line 353, in main_wrap
    result = await self.awaitable(*args, **kwargs)
  File "/home/v4proxy/front/views.py", line 67, in proxy_check
    return render(request, 'front/proxy_check.html', {'form': form, 'result': result , 'a' :results })
  File "/home/v4proxy/env/lib/python3.10/site-packages/django/shortcuts.py", line 24, in render
    content = loader.render_to_string(template_name, context, request, using=using)
  File "/home/v4proxy/env/lib/python3.10/site-packages/django/template/loader.py", line 62, in render_to_string
    return template.render(context, request)
  File "/home/v4proxy/env/lib/python3.10/site-packages/django/template/backends/django.py", line 61, in render
    return self.template.render(context)
  File "/home/v4proxy/env/lib/python3.10/site-packages/django/template/base.py", line 175, in render
    return self._render(context)
  File "/home/v4proxy/env/lib/python3.10/site-packages/django/template/base.py", line 167, in _render
    return self.nodelist.render(context)
  File "/home/v4proxy/env/lib/python3.10/site-packages/django/template/base.py", line 1005, in render
    return SafeString("".join([node.render_annotated(context) for node in self]))
  File "/home/v4proxy/env/lib/python3.10/site-packages/django/template/base.py", line 1005, in <listcomp>
    return SafeString("".join([node.render_annotated(context) for node in self]))
  File "/home/v4proxy/env/lib/python3.10/site-packages/django/template/base.py", line 966, in render_annotated
    return self.render(context)
  File "/home/v4proxy/env/lib/python3.10/site-packages/django/template/defaulttags.py", line 321, in render
    return nodelist.render(context)
  File "/home/v4proxy/env/lib/python3.10/site-packages/django/template/base.py", line 1005, in render
    return SafeString("".join([node.render_annotated(context) for node in self]))
  File "/home/v4proxy/env/lib/python3.10/site-packages/django/template/base.py", line 1005, in <listcomp>
    return SafeString("".join([node.render_annotated(context) for node in self]))
  File "/home/v4proxy/env/lib/python3.10/site-packages/django/template/base.py", line 966, in render_annotated
    return self.render(context)
  File "/home/v4proxy/env/lib/python3.10/site-packages/django/template/defaulttags.py", line 226, in render
    raise ValueError(
ValueError: Need 4 values to unpack in for loop; got 2. 
Internal Server Error: /proxy_check
Traceback (most recent call last):
  File "/home/v4proxy/env/lib/python3.10/site-packages/django/core/handlers/exception.py", line 55, in inner
    response = get_response(request)
  File "/home/v4proxy/env/lib/python3.10/site-packages/django/core/handlers/base.py", line 197, in _get_response
    response = wrapped_callback(request, *callback_args, **callback_kwargs)
  File "/home/v4proxy/env/lib/python3.10/site-packages/asgiref/sync.py", line 277, in __call__
    return call_result.result()
  File "/usr/lib/python3.10/concurrent/futures/_base.py", line 451, in result
    return self.__get_result()
  File "/usr/lib/python3.10/concurrent/futures/_base.py", line 403, in __get_result
    raise self._exception
  File "/home/v4proxy/env/lib/python3.10/site-packages/asgiref/sync.py", line 353, in main_wrap
    result = await self.awaitable(*args, **kwargs)
  File "/home/v4proxy/front/views.py", line 60, in proxy_check
    results = await check_proxy(proxy_list)  # Asenkron fonksiyonu await ile çağırın
  File "/home/v4proxy/front/views.py", line 24, in check_proxy
    results = await asyncio.gather(*tasks)
  File "/home/v4proxy/front/views.py", line 40, in check_proxy_async
    country = await get_country(ip) if is_active else 'Bilinmiyor'
TypeError: object str can't be used in 'await' expression
Internal Server Error: /panel/view_proxy/3
Traceback (most recent call last):
  File "/home/v4proxy/env/lib/python3.10/site-packages/django/core/handlers/exception.py", line 55, in inner
    response = get_response(request)
  File "/home/v4proxy/env/lib/python3.10/site-packages/django/core/handlers/base.py", line 197, in _get_response
    response = wrapped_callback(request, *callback_args, **callback_kwargs)
  File "/home/v4proxy/env/lib/python3.10/site-packages/django/contrib/auth/decorators.py", line 23, in _wrapper_view
    return view_func(request, *args, **kwargs)
  File "/home/v4proxy/panel/views.py", line 256, in view_proxy
    ssh.connect(ip, username=username, password=password)
  File "/home/v4proxy/env/lib/python3.10/site-packages/paramiko/client.py", line 485, in connect
    self._auth(
  File "/home/v4proxy/env/lib/python3.10/site-packages/paramiko/client.py", line 818, in _auth
    raise saved_exception
  File "/home/v4proxy/env/lib/python3.10/site-packages/paramiko/client.py", line 805, in _auth
    self._transport.auth_password(username, password)
  File "/home/v4proxy/env/lib/python3.10/site-packages/paramiko/transport.py", line 1587, in auth_password
    return self.auth_handler.wait_for_response(my_event)
  File "/home/v4proxy/env/lib/python3.10/site-packages/paramiko/auth_handler.py", line 263, in wait_for_response
    raise e
paramiko.ssh_exception.AuthenticationException: Authentication failed.
Internal Server Error: /panel/view_proxy/40
Traceback (most recent call last):
  File "/home/v4proxy/env/lib/python3.10/site-packages/django/core/handlers/exception.py", line 55, in inner
    response = get_response(request)
  File "/home/v4proxy/env/lib/python3.10/site-packages/django/core/handlers/base.py", line 197, in _get_response
    response = wrapped_callback(request, *callback_args, **callback_kwargs)
  File "/home/v4proxy/env/lib/python3.10/site-packages/django/contrib/auth/decorators.py", line 23, in _wrapper_view
    return view_func(request, *args, **kwargs)
  File "/home/v4proxy/panel/views.py", line 264, in view_proxy
    if line.startswith('proxy', 'socks'):
TypeError: slice indices must be integers or None or have an __index__ method
Internal Server Error: /panel/view_proxy/40
Traceback (most recent call last):
  File "/home/v4proxy/env/lib/python3.10/site-packages/django/core/handlers/exception.py", line 55, in inner
    response = get_response(request)
  File "/home/v4proxy/env/lib/python3.10/site-packages/django/core/handlers/base.py", line 197, in _get_response
    response = wrapped_callback(request, *callback_args, **callback_kwargs)
  File "/home/v4proxy/env/lib/python3.10/site-packages/django/contrib/auth/decorators.py", line 23, in _wrapper_view
    return view_func(request, *args, **kwargs)
  File "/home/v4proxy/panel/views.py", line 264, in view_proxy
    if line.startswith('proxy', 'socks'):
TypeError: slice indices must be integers or None or have an __index__ method
Internal Server Error: /panel/view_proxy/40
Traceback (most recent call last):
  File "/home/v4proxy/env/lib/python3.10/site-packages/django/core/handlers/exception.py", line 55, in inner
    response = get_response(request)
  File "/home/v4proxy/env/lib/python3.10/site-packages/django/core/handlers/base.py", line 197, in _get_response
    response = wrapped_callback(request, *callback_args, **callback_kwargs)
  File "/home/v4proxy/env/lib/python3.10/site-packages/django/contrib/auth/decorators.py", line 23, in _wrapper_view
    return view_func(request, *args, **kwargs)
  File "/home/v4proxy/panel/views.py", line 264, in view_proxy
    if line.startswith('proxy', 'socks5'):
TypeError: slice indices must be integers or None or have an __index__ method
Internal Server Error: /panel/view_proxy/40
Traceback (most recent call last):
  File "/home/v4proxy/env/lib/python3.10/site-packages/django/core/handlers/exception.py", line 55, in inner
    response = get_response(request)
  File "/home/v4proxy/env/lib/python3.10/site-packages/django/core/handlers/base.py", line 197, in _get_response
    response = wrapped_callback(request, *callback_args, **callback_kwargs)
  File "/home/v4proxy/env/lib/python3.10/site-packages/django/contrib/auth/decorators.py", line 23, in _wrapper_view
    return view_func(request, *args, **kwargs)
  File "/home/v4proxy/panel/views.py", line 264, in view_proxy
    if line.startswith('proxy', 'socks5'):
TypeError: slice indices must be integers or None or have an __index__ method
Internal Server Error: /
Traceback (most recent call last):
  File "/home/v4proxy/env/lib/python3.10/site-packages/django/contrib/sessions/backends/base.py", line 187, in _get_session
    return self._session_cache
AttributeError: 'SessionStore' object has no attribute '_session_cache'

During handling of the above exception, another exception occurred:

Traceback (most recent call last):
  File "/home/v4proxy/env/lib/python3.10/site-packages/django/db/backends/base/base.py", line 289, in ensure_connection
    self.connect()
  File "/home/v4proxy/env/lib/python3.10/site-packages/django/utils/asyncio.py", line 26, in inner
    return func(*args, **kwargs)
  File "/home/v4proxy/env/lib/python3.10/site-packages/django/db/backends/base/base.py", line 270, in connect
    self.connection = self.get_new_connection(conn_params)
  File "/home/v4proxy/env/lib/python3.10/site-packages/django/utils/asyncio.py", line 26, in inner
    return func(*args, **kwargs)
  File "/home/v4proxy/env/lib/python3.10/site-packages/django/db/backends/mysql/base.py", line 247, in get_new_connection
    connection = Database.connect(**conn_params)
  File "/home/v4proxy/env/lib/python3.10/site-packages/MySQLdb/__init__.py", line 121, in Connect
    return Connection(*args, **kwargs)
  File "/home/v4proxy/env/lib/python3.10/site-packages/MySQLdb/connections.py", line 193, in __init__
    super().__init__(*args, **kwargs2)
MySQLdb.OperationalError: (2002, "Can't connect to local MySQL server through socket '/var/run/mysqld/mysqld.sock' (2)")

The above exception was the direct cause of the following exception:

Traceback (most recent call last):
  File "/home/v4proxy/env/lib/python3.10/site-packages/django/core/handlers/exception.py", line 55, in inner
    response = get_response(request)
  File "/home/v4proxy/env/lib/python3.10/site-packages/allauth/account/middleware.py", line 15, in __call__
    self._remove_dangling_login(request, response)
  File "/home/v4proxy/env/lib/python3.10/site-packages/allauth/account/middleware.py", line 37, in _remove_dangling_login
    if "account_login" in request.session:
  File "/home/v4proxy/env/lib/python3.10/site-packages/django/contrib/sessions/backends/base.py", line 50, in __contains__
    return key in self._session
  File "/home/v4proxy/env/lib/python3.10/site-packages/django/contrib/sessions/backends/base.py", line 192, in _get_session
    self._session_cache = self.load()
  File "/home/v4proxy/env/lib/python3.10/site-packages/django/contrib/sessions/backends/db.py", line 42, in load
    s = self._get_session_from_db()
  File "/home/v4proxy/env/lib/python3.10/site-packages/django/contrib/sessions/backends/db.py", line 32, in _get_session_from_db
    return self.model.objects.get(
  File "/home/v4proxy/env/lib/python3.10/site-packages/django/db/models/manager.py", line 87, in manager_method
    return getattr(self.get_queryset(), name)(*args, **kwargs)
  File "/home/v4proxy/env/lib/python3.10/site-packages/django/db/models/query.py", line 633, in get
    num = len(clone)
  File "/home/v4proxy/env/lib/python3.10/site-packages/django/db/models/query.py", line 380, in __len__
    self._fetch_all()
  File "/home/v4proxy/env/lib/python3.10/site-packages/django/db/models/query.py", line 1881, in _fetch_all
    self._result_cache = list(self._iterable_class(self))
  File "/home/v4proxy/env/lib/python3.10/site-packages/django/db/models/query.py", line 91, in __iter__
    results = compiler.execute_sql(
  File "/home/v4proxy/env/lib/python3.10/site-packages/django/db/models/sql/compiler.py", line 1560, in execute_sql
    cursor = self.connection.cursor()
  File "/home/v4proxy/env/lib/python3.10/site-packages/django/utils/asyncio.py", line 26, in inner
    return func(*args, **kwargs)
  File "/home/v4proxy/env/lib/python3.10/site-packages/django/db/backends/base/base.py", line 330, in cursor
    return self._cursor()
  File "/home/v4proxy/env/lib/python3.10/site-packages/django/db/backends/base/base.py", line 306, in _cursor
    self.ensure_connection()
  File "/home/v4proxy/env/lib/python3.10/site-packages/django/utils/asyncio.py", line 26, in inner
    return func(*args, **kwargs)
  File "/home/v4proxy/env/lib/python3.10/site-packages/django/db/backends/base/base.py", line 288, in ensure_connection
    with self.wrap_database_errors:
  File "/home/v4proxy/env/lib/python3.10/site-packages/django/db/utils.py", line 91, in __exit__
    raise dj_exc_value.with_traceback(traceback) from exc_value
  File "/home/v4proxy/env/lib/python3.10/site-packages/django/db/backends/base/base.py", line 289, in ensure_connection
    self.connect()
  File "/home/v4proxy/env/lib/python3.10/site-packages/django/utils/asyncio.py", line 26, in inner
    return func(*args, **kwargs)
  File "/home/v4proxy/env/lib/python3.10/site-packages/django/db/backends/base/base.py", line 270, in connect
    self.connection = self.get_new_connection(conn_params)
  File "/home/v4proxy/env/lib/python3.10/site-packages/django/utils/asyncio.py", line 26, in inner
    return func(*args, **kwargs)
  File "/home/v4proxy/env/lib/python3.10/site-packages/django/db/backends/mysql/base.py", line 247, in get_new_connection
    connection = Database.connect(**conn_params)
  File "/home/v4proxy/env/lib/python3.10/site-packages/MySQLdb/__init__.py", line 121, in Connect
    return Connection(*args, **kwargs)
  File "/home/v4proxy/env/lib/python3.10/site-packages/MySQLdb/connections.py", line 193, in __init__
    super().__init__(*args, **kwargs2)
django.db.utils.OperationalError: (2002, "Can't connect to local MySQL server through socket '/var/run/mysqld/mysqld.sock' (2)")
